[2025-07-08T07:32:03.991+0000] {taskinstance.py:1157} INFO - Dependencies all met for dep_context=non-requeueable deps ti=<TaskInstance: minio_file_compressor.compress_file manual__2025-07-08T07:31:37.654441+00:00 [queued]>
[2025-07-08T07:32:04.139+0000] {taskinstance.py:1157} INFO - Dependencies all met for dep_context=requeueable deps ti=<TaskInstance: minio_file_compressor.compress_file manual__2025-07-08T07:31:37.654441+00:00 [queued]>
[2025-07-08T07:32:04.143+0000] {taskinstance.py:1359} INFO - Starting attempt 1 of 2
[2025-07-08T07:32:04.282+0000] {taskinstance.py:1380} INFO - Executing <Task(PythonOperator): compress_file> on 2025-07-08 07:31:37.654441+00:00
[2025-07-08T07:32:04.317+0000] {standard_task_runner.py:57} INFO - Started process 67 to run task
[2025-07-08T07:32:04.344+0000] {standard_task_runner.py:84} INFO - Running: ['***', 'tasks', 'run', 'minio_file_compressor', 'compress_file', 'manual__2025-07-08T07:31:37.654441+00:00', '--job-id', '20', '--raw', '--subdir', 'DAGS_FOLDER/file_compress.py', '--cfg-path', '/tmp/tmp1zko8dt5']
[2025-07-08T07:32:04.355+0000] {standard_task_runner.py:85} INFO - Job 20: Subtask compress_file
[2025-07-08T07:32:04.721+0000] {task_command.py:415} INFO - Running <TaskInstance: minio_file_compressor.compress_file manual__2025-07-08T07:31:37.654441+00:00 [running]> on host 46e48579a505
[2025-07-08T07:32:05.335+0000] {taskinstance.py:1660} INFO - Exporting env vars: AIRFLOW_CTX_DAG_OWNER='***' AIRFLOW_CTX_DAG_ID='minio_file_compressor' AIRFLOW_CTX_TASK_ID='compress_file' AIRFLOW_CTX_EXECUTION_DATE='2025-07-08T07:31:37.654441+00:00' AIRFLOW_CTX_TRY_NUMBER='1' AIRFLOW_CTX_DAG_RUN_ID='manual__2025-07-08T07:31:37.654441+00:00'
[2025-07-08T07:32:05.349+0000] {taskinstance.py:1935} ERROR - Task failed with exception
Traceback (most recent call last):
  File "/home/airflow/.local/lib/python3.8/site-packages/airflow/operators/python.py", line 192, in execute
    return_value = self.execute_callable()
  File "/home/airflow/.local/lib/python3.8/site-packages/airflow/operators/python.py", line 209, in execute_callable
    return self.python_callable(*self.op_args, **self.op_kwargs)
  File "/opt/airflow/dags/file_compress.py", line 169, in process_file_compression
    raise ValueError("object_name not provided in DAG configuration")
ValueError: object_name not provided in DAG configuration
[2025-07-08T07:32:05.498+0000] {taskinstance.py:1398} INFO - Marking task as UP_FOR_RETRY. dag_id=minio_file_compressor, task_id=compress_file, execution_date=20250708T073137, start_date=20250708T073204, end_date=20250708T073205
[2025-07-08T07:32:05.584+0000] {standard_task_runner.py:104} ERROR - Failed to execute job 20 for task compress_file (object_name not provided in DAG configuration; 67)
[2025-07-08T07:32:05.678+0000] {local_task_job_runner.py:228} INFO - Task exited with return code 1
[2025-07-08T07:32:05.814+0000] {taskinstance.py:2776} INFO - 0 downstream tasks scheduled from follow-on schedule check
