[2025-07-08T05:40:38.585+0000] {taskinstance.py:1157} INFO - Dependencies all met for dep_context=non-requeueable deps ti=<TaskInstance: minio_file_compressor.compress_file manual__2025-07-08T05:35:32.543638+00:00 [queued]>
[2025-07-08T05:40:38.621+0000] {taskinstance.py:1157} INFO - Dependencies all met for dep_context=requeueable deps ti=<TaskInstance: minio_file_compressor.compress_file manual__2025-07-08T05:35:32.543638+00:00 [queued]>
[2025-07-08T05:40:38.622+0000] {taskinstance.py:1359} INFO - Starting attempt 2 of 2
[2025-07-08T05:40:38.672+0000] {taskinstance.py:1380} INFO - Executing <Task(PythonOperator): compress_file> on 2025-07-08 05:35:32.543638+00:00
[2025-07-08T05:40:38.684+0000] {standard_task_runner.py:57} INFO - Started process 58 to run task
[2025-07-08T05:40:38.699+0000] {standard_task_runner.py:84} INFO - Running: ['***', 'tasks', 'run', 'minio_file_compressor', 'compress_file', 'manual__2025-07-08T05:35:32.543638+00:00', '--job-id', '5', '--raw', '--subdir', 'DAGS_FOLDER/file_compress.py', '--cfg-path', '/tmp/tmpn9w_drm4']
[2025-07-08T05:40:38.703+0000] {standard_task_runner.py:85} INFO - Job 5: Subtask compress_file
[2025-07-08T05:40:38.881+0000] {task_command.py:415} INFO - Running <TaskInstance: minio_file_compressor.compress_file manual__2025-07-08T05:35:32.543638+00:00 [running]> on host 46e48579a505
[2025-07-08T05:40:39.466+0000] {taskinstance.py:1660} INFO - Exporting env vars: AIRFLOW_CTX_DAG_OWNER='***' AIRFLOW_CTX_DAG_ID='minio_file_compressor' AIRFLOW_CTX_TASK_ID='compress_file' AIRFLOW_CTX_EXECUTION_DATE='2025-07-08T05:35:32.543638+00:00' AIRFLOW_CTX_TRY_NUMBER='2' AIRFLOW_CTX_DAG_RUN_ID='manual__2025-07-08T05:35:32.543638+00:00'
[2025-07-08T05:40:39.472+0000] {taskinstance.py:1935} ERROR - Task failed with exception
Traceback (most recent call last):
  File "/home/airflow/.local/lib/python3.8/site-packages/airflow/operators/python.py", line 192, in execute
    return_value = self.execute_callable()
  File "/home/airflow/.local/lib/python3.8/site-packages/airflow/operators/python.py", line 209, in execute_callable
    return self.python_callable(*self.op_args, **self.op_kwargs)
  File "/opt/airflow/dags/file_compress.py", line 176, in process_file_compression
    raise ValueError("object_name not provided in DAG configuration")
ValueError: object_name not provided in DAG configuration
[2025-07-08T05:40:39.527+0000] {taskinstance.py:1398} INFO - Marking task as FAILED. dag_id=minio_file_compressor, task_id=compress_file, execution_date=20250708T053532, start_date=20250708T054038, end_date=20250708T054039
[2025-07-08T05:40:39.677+0000] {standard_task_runner.py:104} ERROR - Failed to execute job 5 for task compress_file (object_name not provided in DAG configuration; 58)
[2025-07-08T05:40:39.776+0000] {local_task_job_runner.py:228} INFO - Task exited with return code 1
[2025-07-08T05:40:40.306+0000] {taskinstance.py:2776} INFO - 0 downstream tasks scheduled from follow-on schedule check
